Traceback (most recent call last):
  File "/home/arc/miniconda3/envs/real-valued-acs-system/lib/python3.9/site-packages/nbclient/client.py", line 618, in _async_poll_for_reply
    msg = await ensure_async(self.kc.shell_channel.get_msg(timeout=new_timeout))
  File "/home/arc/miniconda3/envs/real-valued-acs-system/lib/python3.9/site-packages/nbclient/util.py", line 96, in ensure_async
    result = await obj
  File "/home/arc/miniconda3/envs/real-valued-acs-system/lib/python3.9/site-packages/jupyter_client/channels.py", line 230, in get_msg
    raise Empty
_queue.Empty

During handling of the above exception, another exception occurred:

Traceback (most recent call last):
  File "/home/arc/miniconda3/envs/real-valued-acs-system/lib/python3.9/site-packages/jupyter_cache/executors/utils.py", line 51, in single_nb_execution
    executenb(
  File "/home/arc/miniconda3/envs/real-valued-acs-system/lib/python3.9/site-packages/nbclient/client.py", line 1085, in execute
    return NotebookClient(nb=nb, resources=resources, km=km, **kwargs).execute()
  File "/home/arc/miniconda3/envs/real-valued-acs-system/lib/python3.9/site-packages/nbclient/util.py", line 84, in wrapped
    return just_run(coro(*args, **kwargs))
  File "/home/arc/miniconda3/envs/real-valued-acs-system/lib/python3.9/site-packages/nbclient/util.py", line 62, in just_run
    return loop.run_until_complete(coro)
  File "/home/arc/miniconda3/envs/real-valued-acs-system/lib/python3.9/asyncio/base_events.py", line 642, in run_until_complete
    return future.result()
  File "/home/arc/miniconda3/envs/real-valued-acs-system/lib/python3.9/site-packages/nbclient/client.py", line 551, in async_execute
    await self.async_execute_cell(
  File "/home/arc/miniconda3/envs/real-valued-acs-system/lib/python3.9/site-packages/nbclient/client.py", line 830, in async_execute_cell
    exec_reply = await self.task_poll_for_reply
  File "/home/arc/miniconda3/envs/real-valued-acs-system/lib/python3.9/site-packages/nbclient/client.py", line 642, in _async_poll_for_reply
    await self._async_handle_timeout(timeout, cell)
  File "/home/arc/miniconda3/envs/real-valued-acs-system/lib/python3.9/site-packages/nbclient/client.py", line 689, in _async_handle_timeout
    raise CellTimeoutError.error_from_timeout_and_cell(
nbclient.exceptions.CellTimeoutError: A cell timed out while it was being executed, after 30 seconds.
The message was: Cell execution timed out.
Here is a preview of the cell contents:
-------------------
['def train_bayes_model(dfs, query_condition, field):', '    data_arr = pd.concat(dfs).query(query_condition)[field].to_numpy()', '    bayes_model = bayes_estimate(data_arr)', "    return bayes_model['mu'], bayes_model['std']", '']
...
['    reliable_table_data[bins] = list(map(print_row, models))', '', '# Add glue objects', "glue('rmpx_average_reward', print_bayes_table(average_rewards_data), display=False)", "glue('rmpx_bayes_reliable_classifies', print_bayes_table(reliable_table_data), display=False)"]
-------------------

